Workbook
Name UPDATE: 'Data Sheet'!$E$1

Sheet Data Sheet
A1: COMPANY NAME | B1: ESCORTS KUBOTA LTD | E1: =IF(B2<>B3, "A NEW VERSION OF THE WORKSHEET IS AVAILABLE", "")
A2: LATEST VERSION | B2: 2.1 | E2: PLEASE DO NOT MAKE ANY CHANGES TO THIS SHEET
A3: CURRENT VERSION | B3: 2.1
A5: META
A6: Number of shares | B6: =IF(B9>0, B9/B8, 0) -> 11.18778
A7: Face Value | B7: 10
A8: Current Price | B8: 3306
A9: Market Capitalization | B9: 36986.8
C12: =B18+B20+B21+B22-B19 -> 2932.37
A15: PROFIT & LOSS
A16: Report Date | B16: 42460 | C16: 42825 | D16: 43190 | E16: 43555 | F16: 43921 | G16: 44286 | H16: 44651 | I16: 45016 | J16: 45382 | K16: 45747
A17: Sales | B17: 3431.99 | C17: 4145.33 | D17: 5059.34 | E17: 6262.02 | F17: 5810.09 | G17: 7014.42 | H17: 7282.65 | I17: 8428.69 | J17: 9803.59 | K17: 10243.88
A18: Raw Material Cost | B18: 2409.31 | C18: 2877.78 | D18: 3426.78 | E18: 4481.47 | F18: 3846.68 | G18: 4514.72 | H18: 5045.45 | I18: 6286.53 | J18: 7147.97 | K18: 7066.61
A19: Change in Inventory | B19: 24.88 | C19: 46.49 | D19: 19.36 | E19: 204.54 | F19: 5.58 | G19: -129.92 | H19: 66.94 | I19: 163.65 | J19: 185.97 | K19: -188.53
A20: Power and Fuel | B20: 36.01 | C20: 38.84 | D20: 38.2 | E20: 45.44 | F20: 40.07 | G20: 38.37 | H20: 40.59 | I20: 45.84 | J20: 50.59 | K20: 46.37
A21: Other Mfr. Exp | B21: 98.37 | C21: 137.75 | D21: 167.41 | E21: 215.43 | F21: 205.6 | G21: 204.74 | H21: 232.41 | I21: 289.65 | J21: 348.14 | K21: 385.06
A22: Employee Cost | B22: 413.56 | C22: 422.1 | D22: 460.47 | E22: 492.76 | F22: 526.59 | G22: 555.41 | H22: 549.41 | I22: 613.83 | J22: 706.01 | K22: 781.22
A23: Selling and admin | B23: 305 | C23: 344.98 | D23: 362 | E23: 431.46 | F23: 423.61 | G23: 370.27 | H23: 394.61 | I23: 491.31 | J23: 472.55 | K23: 488.89
A24: Other Expenses | B24: 33.67 | C24: 102.59 | D24: 70.49 | E24: 77.43 | F24: 111.8 | G24: 74.97 | H24: 121.06 | I24: 95.14 | J24: 133.93 | K24: 123.01
A25: Other Income | B25: 30.66 | C25: 35.85 | D25: 58.44 | E25: 99.19 | F25: 88.38 | G25: 160.38 | H25: 173.8 | I25: 227.88 | J25: 525.37 | K25: 600.53
A26: Depreciation | B26: 58.13 | C26: 63.42 | D26: 73.22 | E26: 87.21 | F26: 107.22 | G26: 118.28 | H26: 132.06 | I26: 150.06 | J26: 224.06 | K26: 243.65
A27: Interest | B27: 51.06 | C27: 32.21 | D27: 29.49 | E27: 19.54 | F27: 17.23 | G27: 13.34 | H27: 14.97 | I27: 13.27 | J27: 41.66 | K27: 29.17
... A31: Dividend Amount | B31: 14.71 | C31: 18.39 | D31: 24.52 | E31: 30.64 | F31: 30.64 | G31: 101.12 | H31: 92.36 | I31: 92.36 | J31: 198.9 | K31: 313.26
A40: Quarters
A41: Report Date | B41: 44926 | C41: 45016 | D41: 45107 | E41: 45199 | F41: 45291 | G41: 45382 | H41: 45473 | I41: 45565 | J41: 45657 | K41: 45747
A42: Sales | B42: 2291.35 | C42: 2214.48 | D42: 2355.17 | E42: 2477.71 | F42: 2727.61 | G42: 2300.66 | H42: 2818.39 | I42: 2277.25 | J42: 2948.02 | K42: 2444.88
A43: Expenses | B43: 2105.96 | C43: 1981.32 | D43: 2024.12 | E43: 2213.52 | F43: 2402.32 | G43: 2015.25 | H43: 2450.99 | I43: 2047.43 | J43: 2615.74 | K43: 2157.63
A44: Other Income | B44: 91.68 | C44: 86.46 | D44: 99.02 | E44: 93.75 | F44: 128.6 | G44: 132.77 | H44: 103.04 | I44: 140.05 | J44: 142.6 | K44: 177.6
A45: Depreciation | B45: 37.97 | C45: 38.37 | D45: 40.3 | E45: 58.34 | F45: 56.62 | G45: 59.24 | H45: 61.63 | I45: 61.07 | J45: 61.53 | K45: 61.97
A46: Interest | B46: 3.48 | C46: 3.63 | D46: 3.43 | E46: 9.43 | F46: 11.16 | G46: 11.66 | H46: 10.73 | I46: 9.79 | J46: 3.54 | K46: 5.14
A47: Profit before tax | B47: 235.62 | C47: 277.62 | D47: 386.34 | E47: 290.17 | F47: 386.11 | G47: 347.28 | H47: 398.08 | I47: 299.01 | J47: 409.81 | K47: 397.74
A48: Tax | B48: 54.82 | C48: 61.16 | D48: 96.45 | E48: 79.66 | F48: 87.59 | G48: 77.3 | H48: 96.4 | I48: -25.21 | J48: 89.18 | K48: 79.32
A49: Net profit | B49: 180.82 | C49: 216.49 | D49: 289.9 | E49: 210.53 | F49: 298.51 | G49: 269.99 | H49: 301.65 | I49: 324.23 | J49: 320.64 | K49: 318.42
A50: Operating Profit | B50: 185.39 | C50: 233.16 | D50: 331.05 | E50: 264.19 | F50: 325.29 | G50: 285.41 | H50: 367.4 | I50: 229.82 | J50: 332.28 | K50: 287.25
A55: BALANCE SHEET
A56: Report Date | B56: 42460 | C56: 42825 | D56: 43190 | E56: 43555 | F56: 43921 | G56: 44286 | H56: 44651 | I56: 45016 | J56: 45382 | K56: 45747
A57: Equity Share Capital | B57: 122.58 | C57: 122.58 | D57: 122.58 | E57: 122.58 | F57: 122.58 | G57: 134.83 | H57: 131.94 | I57: 131.94 | J57: 110.5 | K57: 111.88
A58: Reserves | B58: 1343.9 | C58: 1498.35 | D58: 2092.56 | E58: 2550.91 | F58: 2994.82 | G58: 4891.3 | H58: 7467.96 | I58: 8054.77 | J58: 9278.01 | K58: 10254.92
A59: Borrowings | B59: 368.12 | C59: 265.43 | D59: 51.09 | E59: 280.96 | F59: 47.67 | G59: 60.61 | H59: 51.95 | I59: 57.3 | J59: 448.46 | K59: 105.18
A60: Other Liabilities | B60: 1133.58 | C60: 1312.86 | D60: 1706.3 | E60: 1752.52 | F60: 1848.89 | G60: 1791.43 | H60: 1455.89 | I60: 1840.81 | J60: 2563.39 | K60: 2622.71
...

Sheet HISTORICAL FS
B2: ="HISTORICAL FINANCIAL STATEMENT - "&'Data Sheet'!B1 -> HISTORICAL FINANCIAL STATEMENT - ESCORTS KUBOTA LTD
B3: YEARS | C3: ='Data Sheet'!B16 -> 42460 | D3: ='Data Sheet'!C16 -> 42825 | E3: ='Data Sheet'!D16 -> 43190 | F3: ='Data Sheet'!E16 -> 43555 | G3: ='Data Sheet'!F16 -> 43921 | H3: ='Data Sheet'!G16 -> 44286 | I3: ='Data Sheet'!H16 -> 44651 | J3: ='Data Sheet'!I16 -> 45016 | ... L3: ='Data Sheet'!K16 -> 45747 | M3: LTM
A4: # | B4: INCOME STATEMENT
B5: Sales growth | C5: =IFERROR('Data Sheet'!B17,0) -> 3431.99 | D5: =IFERROR('Data Sheet'!C17,0) -> 4145.33 | E5: =IFERROR('Data Sheet'!D17,0) -> 5059.34 | F5: =IFERROR('Data Sheet'!E17,0) -> 6262.02 | G5: =IFERROR('Data Sheet'!F17,0) -> 5810.09 | H5: =IFERROR('Data Sheet'!G17,0) -> 7014.42 | I5: =IFERROR('Data Sheet'!H17,0) -> 7282.65 | J5: =IFERROR('Data Sheet'!I17,0) -> 8428.69 | ... L5: =IFERROR('Data Sheet'!K17,0) -> 10243.88 | M5: =IFERROR(SUM('Data Sheet'!H42:K42),0) -> 10488.54
B6: Sales growth | C6: - | D6: =D5/C5-1 -> 0.20785026 | E6: =E5/D5-1 -> 0.22049149 | F6: =F5/E5-1 -> 0.2377148 | G6: =G5/F5-1 -> -0.072170003 | H6: =H5/G5-1 -> 0.2072825 | I6: =I5/H5-1 -> 0.038239797 | J6: =J5/I5-1 -> 0.15736579 | K6: =K5/J5-1 -> 0.16312143 | ... M6: =M5/L5-1 -> 0.023883529
B8: COGS | C8: =IFERROR(SUM('Data Sheet'!B18,'Data Sheet'!B20,'Data Sheet'!B21,'Data Sheet'!B22)-1*'Data Sheet'!B19,0) -> 2932.37 | D8: =IFERROR(SUM('Data Sheet'!C18,'Data Sheet'!C20,'Data Sheet'!C21,'Data Sheet'!C22)-1*'Data Sheet'!C19,0) -> 3429.98 | E8: =IFERROR(SUM('Data Sheet'!D18,'Data Sheet'!D20,'Data Sheet'!D21,'Data Sheet'!D22)-1*'Data Sheet'!D19,0) -> 4073.5 | F8: =IFERROR(SUM('Data Sheet'!E18,'Data Sheet'!E20,'Data Sheet'!E21,'Data Sheet'!E22)-1*'Data Sheet'!E19,0) -> 5030.56 | G8: =IFERROR(SUM('Data Sheet'!F18,'Data Sheet'!F20,'Data Sheet'!F21,'Data Sheet'!F22)-1*'Data Sheet'!F19,0) -> 4613.36 | H8: =IFERROR(SUM('Data Sheet'!G18,'Data Sheet'!G20,'Data Sheet'!G21,'Data Sheet'!G22)-1*'Data Sheet'!G19,0) -> 5443.16 | I8: =IFERROR(SUM('Data Sheet'!H18,'Data Sheet'!H20,'Data Sheet'!H21,'Data Sheet'!H22)-1*'Data Sheet'!H19,0) -> 5800.92 | J8: =IFERROR(SUM('Data Sheet'!I18,'Data Sheet'!I20,'Data Sheet'!I21,'Data Sheet'!I22)-1*'Data Sheet'!I19,0) -> 7072.2 | ... L8: =IFERROR(SUM('Data Sheet'!K18,'Data Sheet'!K20,'Data Sheet'!K21,'Data Sheet'!K22)-1*'Data Sheet'!K19,0) -> 8467.79 | M8: =IFERROR(SUM('Data Sheet'!H43:K43),0) -> 9271.79
B9: COGS % of sales | C9: =C8/C5 -> 0.85442265 | D9: =D8/D5 -> 0.82743232 | E9: =E8/E5 -> 0.80514454 | F9: =F8/F5 -> 0.80334461 | G9: =G8/G5 -> 0.79402557 | H9: =H8/H5 -> 0.77599573 | I9: =I8/I5 -> 0.79653972 | J9: =J8/J5 -> 0.83906277 | ... L9: =L8/L5 -> 0.82661941 | M9: -
B11: GROSS PROFIT | C11: =C5-C8 -> 499.62 | D11: =D5-D8 -> 715.35 | E11: =E5-E8 -> 985.84 | F11: =F5-F8 -> 1231.46 | G11: =G5-G8 -> 1196.73 | H11: =H5-H8 -> 1571.26 | I11: =I5-I8 -> 1481.73 | J11: =J5-J8 -> 1356.49 | ... M11: =M5-M8 -> 1216.75
B12: Gross margin | C12: =C11/C5 -> 0.14557735 | D12: =D11/D5 -> 0.17256768 | E12: =E11/E5 -> 0.19485546 | F12: =F11/F5 -> 0.19665539 | G12: =G11/G5 -> 0.20597443 | H12: =H11/H5 -> 0.22400427 | I12: =I11/I5 -> 0.20346028 | J12: =J11/J5 -> 0.16093723 | ... M12: =M11/M5 -> 0.11600757
B14: SELLING AND GENERAL EXPENSES | C14: =IFERROR(SUM('Data Sheet'!B23,'Data Sheet'!B24),0) -> 338.67 | D14: =IFERROR(SUM('Data Sheet'!C23,'Data Sheet'!C24),0) -> 447.57 | E14: =IFERROR(SUM('Data Sheet'!D23,'Data Sheet'!D24),0) -> 432.49 | F14: =IFERROR(SUM('Data Sheet'!E23,'Data Sheet'!E24),0) -> 508.89 | G14: =IFERROR(SUM('Data Sheet'!F23,'Data Sheet'!F24),0) -> 535.41 | H14: =IFERROR(SUM('Data Sheet'!G23,'Data Sheet'!G24),0) -> 445.24 | I14: =IFERROR(SUM('Data Sheet'!H23,'Data Sheet'!H24),0) -> 515.67 | J14: =IFERROR(SUM('Data Sheet'!I23,'Data Sheet'!I24),0) -> 586.45 | ... L14: =IFERROR(SUM('Data Sheet'!K23,'Data Sheet'!K24),0) -> 611.9
B15: S&G EX % of sales | C15: =C14/C5 -> 0.098680357 | D15: =D14/D5 -> 0.10796969 | E15: =E14/E5 -> 0.085483482 | F15: =F14/F5 -> 0.081266109 | G15: =G14/G5 -> 0.092151757 | H15: =H14/H5 -> 0.063474956 | I15: =I14/I5 -> 0.070808016 | J15: =J14/J5 -> 0.069577835 | ... M15: =M14/M5 -> 0
B17: EBITDA | C17: =C11-C14 -> 160.95 | D17: =D11-D14 -> 267.78 | E17: =E11-E14 -> 553.35 | F17: =F11-F14 -> 722.57 | G17: =G11-G14 -> 661.32 | H17: =H11-H14 -> 1126.02 | I17: =I11-I14 -> 966.06 | J17: =J11-J14 -> 770.04 | ... M17: =M11-M14 -> 1216.75
B18: EBITDA margins | C18: =C17/C5 -> 0.04689699 | D18: =D17/D5 -> 0.064597993 | E18: =E17/E5 -> 0.10937197 | F18: =F17/F5 -> 0.11538928 | G18: =G17/G5 -> 0.11382268 | H18: =H17/H5 -> 0.16052931 | I18: =I17/I5 -> 0.13265226 | J18: =J17/J5 -> 0.091359393 | ... M18: =M17/M5 -> 0.11600757
B20: INTEREST | C20: =IFERROR('Data Sheet'!B27,0) -> 51.06 | D20: =IFERROR('Data Sheet'!C27,0) -> 32.21 | E20: =IFERROR('Data Sheet'!D27,0) -> 29.49 | F20: =IFERROR('Data Sheet'!E27,0) -> 19.54 | G20: =IFERROR('Data Sheet'!F27,0) -> 17.23 | H20: =IFERROR('Data Sheet'!G27,0) -> 13.34 | I20: =IFERROR('Data Sheet'!H27,0) -> 14.97 | J20: =IFERROR('Data Sheet'!I27,0) -> 13.27 | ... L20: =IFERROR('Data Sheet'!K27,0) -> 29.17 | M20: =IFERROR(SUM('Data Sheet'!H46:K46),0) -> 29.2
B21: interest % of sales | C21: =C20/C5 -> 0.014877666 | D21: =D20/D5 -> 0.0077701896 | E21: =E20/E5 -> 0.0058288235 | F21: =F20/F5 -> 0.0031203988 | G21: =G20/G5 -> 0.0029655307 | H21: =H20/H5 -> 0.0019017966 | I21: =I20/I5 -> 0.0020555704 | J21: =J20/J5 -> 0.0015743846 | ... M21: =M20/M5 -> 0.0027839909
B23: DEPRICIATION | C23: =IFERROR('Data Sheet'!B26,0) -> 58.13 | D23: =IFERROR('Data Sheet'!C26,0) -> 63.42 | E23: =IFERROR('Data Sheet'!D26,0) -> 73.22 | F23: =IFERROR('Data Sheet'!E26,0) -> 87.21 | G23: =IFERROR('Data Sheet'!F26,0) -> 107.22 | H23: =IFERROR('Data Sheet'!G26,0) -> 118.28 | I23: =IFERROR('Data Sheet'!H26,0) -> 132.06 | J23: =IFERROR('Data Sheet'!I26,0) -> 150.06 | ... L23: =IFERROR('Data Sheet'!K26,0) -> 243.65 | M23: =IFERROR(SUM('Data Sheet'!H45:K45),0) -> 246.2
B24: Depriciation % of sales | C24: =C23/C5 -> 0.016937695 | D24: =D23/D5 -> 0.015299144 | E24: =E23/E5 -> 0.014472243 | F24: =F23/F5 -> 0.013926816 | G24: =G23/G5 -> 0.018454103 | H24: =H23/H5 -> 0.016862406 | I24: =I23/I5 -> 0.018133509 | J24: =J23/J5 -> 0.017803478 | ... M24: =M23/M5 -> 0.023473238
B26: EARNINGS BEFORE TAXES | C26: =IFERROR(C17-SUM(C20,C23),0) -> 51.76 | D26: =IFERROR(D17-SUM(D20,D23),0) -> 172.15 | E26: =IFERROR(E17-SUM(E20,E23),0) -> 450.64 | F26: =IFERROR(F17-SUM(F20,F23),0) -> 615.82 | G26: =IFERROR(G17-SUM(G20,G23),0) -> 536.87 | H26: =IFERROR(H17-SUM(H20,H23),0) -> 994.4 | I26: =IFERROR(I17-SUM(I20,I23),0) -> 819.03 | J26: =IFERROR(J17-SUM(J20,J23),0) -> 606.71 | ... M26: =IFERROR(M17-SUM(M20,M23),0) -> 941.35
B27: EBT % of sales | C27: =C26/C5 -> 0.015081629 | D27: =D26/D5 -> 0.04152866 | E27: =E26/E5 -> 0.089070906 | F27: =F26/F5 -> 0.098342069 | G27: =G26/G5 -> 0.092403044 | H27: =H26/H5 -> 0.14176511 | I27: =I26/I5 -> 0.11246318 | J27: =J26/J5 -> 0.07198153 | ... M27: =M26/M5 -> 0.089750337
B29: TAX | C29: =IFERROR('Data Sheet'!B29,0) -> 12.27 | D29: =IFERROR('Data Sheet'!C29,0) -> 77.25 | E29: =IFERROR('Data Sheet'!D29,0) -> 162.49 | F29: =IFERROR('Data Sheet'!E29,0) -> 237.11 | G29: =IFERROR('Data Sheet'!F29,0) -> 153.53 | H29: =IFERROR('Data Sheet'!G29,0) -> 283.15 | I29: =IFERROR('Data Sheet'!H29,0) -> 257.22 | J29: =IFERROR('Data Sheet'!I29,0) -> 197.94 | ... L29: =IFERROR('Data Sheet'!K29,0) -> 226.95 | M29: =IFERROR(SUM('Data Sheet'!H48:K48),0) -> 239.69
B30: Effective tax rate | C30: =C29/C26 -> 0.23705564 | D30: =D29/D26 -> 0.44873657 | E30: =E29/E26 -> 0.36057607 | F30: =F29/F26 -> 0.38503134 | G30: =G29/G26 -> 0.2859724 | H30: =H29/H26 -> 0.28474457 | I30: =I29/I26 -> 0.31405443 | J30: =J29/J26 -> 0.32625142 | ... M30: =M29/M26 -> 0.25462368
B32: NET PROFIT | C32: =C26-C29 -> 39.49 | D32: =D26-D29 -> 94.9 | E32: =E26-E29 -> 288.15 | F32: =F26-F29 -> 378.71 | G32: =G26-G29 -> 383.34 | H32: =H26-H29 -> 711.25 | I32: =I26-I29 -> 561.81 | J32: =J26-J29 -> 408.77 | ... M32: =M26-M29 -> 701.66
B33: Net margin | C33: =C32/C5 -> 0.011506444 | D33: =D32/D5 -> 0.022893232 | E33: =E32/E5 -> 0.056954069 | F33: =F32/F5 -> 0.06047729 | G33: =G32/G5 -> 0.065978324 | H33: =H32/H5 -> 0.10139826 | I33: =I32/I5 -> 0.077143622 | J33: =J32/J5 -> 0.048497453 | ... M33: =M32/M5 -> 0.066897776
B35: NO OF EQUITY SHARES | C35: =IFERROR('Data Sheet'!B93,0) -> 12.26 | D35: =IFERROR('Data Sheet'!C93,0) -> 12.26 | E35: =IFERROR('Data Sheet'!D93,0) -> 12.26 | F35: =IFERROR('Data Sheet'!E93,0) -> 12.26 | G35: =IFERROR('Data Sheet'!F93,0) -> 12.26 | H35: =IFERROR('Data Sheet'!G93,0) -> 13.48 | I35: =IFERROR('Data Sheet'!H93,0) -> 13.19 | J35: =IFERROR('Data Sheet'!I93,0) -> 13.19 | ... L35: =IFERROR('Data Sheet'!K93,0) -> 11.19
B37: EPS | C37: =IFERROR(C32/C35,0) -> 3.221044 | D37: =IFERROR(D32/D35,0) -> 7.7406199 | E37: =IFERROR(E32/E35,0) -> 23.503263 | F37: =IFERROR(F32/F35,0) -> 30.889886 | G37: =IFERROR(G32/G35,0) -> 31.267537 | H37: =IFERROR(H32/H35,0) -> 52.763353 | I37: =IFERROR(I32/I35,0) -> 42.593632 | J37: =IFERROR(J32/J35,0) -> 30.990902 | ... M37: =IFERROR(M32/M35,0) -> 0
B38: EPS % of growth | D38: =D37/C37-1 -> 1.40314 | E38: =E37/D37-1 -> 2.0363541 | F38: =F37/E37-1 -> 0.31428076 | G38: =G37/F37-1 -> 0.012225714 | H38: =H37/G37-1 -> 0.68748033 | I38: =I37/H37-1 -> -0.19274214 | J38: =J37/I37-1 -> -0.27240526 | K38: =K37/J37-1 -> 0.60972654 | ... M38: =M37/L37-1 -> -1
B40: DIVIDEND PER SHARE | C40: =IFERROR('Data Sheet'!B31/'HISTORICAL FS'!C35,0) -> 1.1998369 | D40: =IFERROR('Data Sheet'!C31/'HISTORICAL FS'!D35,0) -> 1.5 | E40: =IFERROR('Data Sheet'!D31/'HISTORICAL FS'!E35,0) -> 2 | F40: =IFERROR('Data Sheet'!E31/'HISTORICAL FS'!F35,0) -> 2.4991843 | G40: =IFERROR('Data Sheet'!F31/'HISTORICAL FS'!G35,0) -> 2.4991843 | H40: =IFERROR('Data Sheet'!G31/'HISTORICAL FS'!H35,0) -> 7.5014837 | I40: =IFERROR('Data Sheet'!H31/'HISTORICAL FS'!I35,0) -> 7.0022745 | J40: =IFERROR('Data Sheet'!I31/'HISTORICAL FS'!J35,0) -> 7.0022745 | ... M40: =IFERROR('Data Sheet'!L31/'HISTORICAL FS'!M35,0) -> 0
B41: Divident payout ratio | C41: =IFERROR(C40/C37,0) -> 0.37249937 | D41: =IFERROR(D40/D37,0) -> 0.19378293 | E41: =IFERROR(E40/E37,0) -> 0.085094569 | F41: =IFERROR(F40/F37,0) -> 0.080906234 | G41: =IFERROR(G40/G37,0) -> 0.079929045 | H41: =IFERROR(H40/H37,0) -> 0.14217223 | I41: =IFERROR(I40/I37,0) -> 0.16439722 | J41: =IFERROR(J40/J37,0) -> 0.22594613 | ... M41: =IFERROR(M40/M37,0) -> 0
B43: RETAINED EARNINGS | C43: =IFERROR(1-C41,0) -> 0.62750063 | D43: =IFERROR(1-D41,0) -> 0.80621707 | E43: =IFERROR(1-E41,0) -> 0.91490543 | F43: =IFERROR(1-F41,0) -> 0.91909377 | G43: =IFERROR(1-G41,0) -> 0.92007096 | H43: =IFERROR(1-H41,0) -> 0.85782777 | I43: =IFERROR(1-I41,0) -> 0.83560278 | J43: =IFERROR(1-J41,0) -> 0.77405387 | ... M43: =IFERROR(1-M41,0) -> 1
A45: # | B45: BALANCE SHEET
B46: Equity share capital | C46: =IFERROR('Data Sheet'!B57,0) -> 122.58 | D46: =IFERROR('Data Sheet'!C57,0) -> 122.58 | E46: =IFERROR('Data Sheet'!D57,0) -> 122.58 | F46: =IFERROR('Data Sheet'!E57,0) -> 122.58 | G46: =IFERROR('Data Sheet'!F57,0) -> 122.58 | H46: =IFERROR('Data Sheet'!G57,0) -> 134.83 | I46: =IFERROR('Data Sheet'!H57,0) -> 131.94 | J46: =IFERROR('Data Sheet'!I57,0) -> 131.94 | ... M46: =IFERROR('Data Sheet'!L57,0) -> 0
B47: Reserves | C47: =IFERROR('Data Sheet'!B58,0) -> 1343.9 | D47: =IFERROR('Data Sheet'!C58,0) -> 1498.35 | E47: =IFERROR('Data Sheet'!D58,0) -> 2092.56 | F47: =IFERROR('Data Sheet'!E58,0) -> 2550.91 | G47: =IFERROR('Data Sheet'!F58,0) -> 2994.82 | H47: =IFERROR('Data Sheet'!G58,0) -> 4891.3 | I47: =IFERROR('Data Sheet'!H58,0) -> 7467.96 | J47: =IFERROR('Data Sheet'!I58,0) -> 8054.77 | ... M47: =IFERROR('Data Sheet'!L58,0) -> 0
B48: Borrowings | C48: =IFERROR('Data Sheet'!B59,0) -> 368.12 | D48: =IFERROR('Data Sheet'!C59,0) -> 265.43 | E48: =IFERROR('Data Sheet'!D59,0) -> 51.09 | F48: =IFERROR('Data Sheet'!E59,0) -> 280.96 | G48: =IFERROR('Data Sheet'!F59,0) -> 47.67 | H48: =IFERROR('Data Sheet'!G59,0) -> 60.61 | I48: =IFERROR('Data Sheet'!H59,0) -> 51.95 | J48: =IFERROR('Data Sheet'!I59,0) -> 57.3 | ... M48: =IFERROR('Data Sheet'!L59,0) -> 0
B49: Other Liabilities | C49: =IFERROR('Data Sheet'!B60,0) -> 1133.58 | D49: =IFERROR('Data Sheet'!C60,0) -> 1312.86 | E49: =IFERROR('Data Sheet'!D60,0) -> 1706.3 | F49: =IFERROR('Data Sheet'!E60,0) -> 1752.52 | G49: =IFERROR('Data Sheet'!F60,0) -> 1848.89 | H49: =IFERROR('Data Sheet'!G60,0) -> 1791.43 | I49: =IFERROR('Data Sheet'!H60,0) -> 1455.89 | J49: =IFERROR('Data Sheet'!I60,0) -> 1840.81 | ... M49: =IFERROR('Data Sheet'!L60,0) -> 0
B50: Total Liabilities | C50: =IFERROR('Data Sheet'!B61,0) -> 2968.18 | D50: =IFERROR('Data Sheet'!C61,0) -> 3199.22 | E50: =IFERROR('Data Sheet'!D61,0) -> 3972.53 | F50: =IFERROR('Data Sheet'!E61,0) -> 4706.97 | G50: =IFERROR('Data Sheet'!F61,0) -> 5013.96 | H50: =IFERROR('Data Sheet'!G61,0) -> 6878.17 | I50: =IFERROR('Data Sheet'!H61,0) -> 9107.74 | J50: =IFERROR('Data Sheet'!I61,0) -> 10084.82 | ... M50: =IFERROR('Data Sheet'!L61,0) -> 0
B52: Fixed Assets net block | C52: =IFERROR('Data Sheet'!B62,0) -> 1539.02 | D52: =IFERROR('Data Sheet'!C62,0) -> 1581.14 | E52: =IFERROR('Data Sheet'!D62,0) -> 1587.8 | F52: =IFERROR('Data Sheet'!E62,0) -> 1647.23 | G52: =IFERROR('Data Sheet'!F62,0) -> 1702.41 | H52: =IFERROR('Data Sheet'!G62,0) -> 1796.23 | I52: =IFERROR('Data Sheet'!H62,0) -> 1841.05 | J52: =IFERROR('Data Sheet'!I62,0) -> 1891.15 | ... M52: =IFERROR('Data Sheet'!L62,0) -> 0
B53: Capital work in progress | C53: =IFERROR('Data Sheet'!B63,0) -> 58.43 | D53: =IFERROR('Data Sheet'!C63,0) -> 34.7 | E53: =IFERROR('Data Sheet'!D63,0) -> 65.72 | F53: =IFERROR('Data Sheet'!E63,0) -> 79.96 | G53: =IFERROR('Data Sheet'!F63,0) -> 124.66 | H53: =IFERROR('Data Sheet'!G63,0) -> 64.69 | I53: =IFERROR('Data Sheet'!H63,0) -> 87.8 | J53: =IFERROR('Data Sheet'!I63,0) -> 113.68 | ... M53: =IFERROR('Data Sheet'!L63,0) -> 0
B54: Investments | C54: =IFERROR('Data Sheet'!B64,0) -> 63.66 | D54: =IFERROR('Data Sheet'!C64,0) -> 212.34 | E54: =IFERROR('Data Sheet'!D64,0) -> 549.04 | F54: =IFERROR('Data Sheet'!E64,0) -> 490.79 | G54: =IFERROR('Data Sheet'!F64,0) -> 797.36 | H54: =IFERROR('Data Sheet'!G64,0) -> 1938.02 | I54: =IFERROR('Data Sheet'!H64,0) -> 4835.84 | J54: =IFERROR('Data Sheet'!I64,0) -> 4766.69 | ... M54: =IFERROR('Data Sheet'!L64,0) -> 0
B55: Other Assets | C55: =IFERROR('Data Sheet'!B65-SUM('Data Sheet'!B67,'Data Sheet'!B68,'Data Sheet'!B69),0) -> 222.31 | D55: =IFERROR('Data Sheet'!C65-SUM('Data Sheet'!C67,'Data Sheet'!C68,'Data Sheet'!C69),0) -> 220.19 | E55: =IFERROR('Data Sheet'!D65-SUM('Data Sheet'!D67,'Data Sheet'!D68,'Data Sheet'!D69),0) -> 294.95 | F55: =IFERROR('Data Sheet'!E65-SUM('Data Sheet'!E67,'Data Sheet'!E68,'Data Sheet'!E69),0) -> 457.22 | G55: =IFERROR('Data Sheet'!F65-SUM('Data Sheet'!F67,'Data Sheet'!F68,'Data Sheet'!F69),0) -> 449.43 | H55: =IFERROR('Data Sheet'!G65-SUM('Data Sheet'!G67,'Data Sheet'!G68,'Data Sheet'!G69),0) -> 381.73 | I55: =IFERROR('Data Sheet'!H65-SUM('Data Sheet'!H67,'Data Sheet'!H68,'Data Sheet'!H69),0) -> 432.03 | J55: =IFERROR('Data Sheet'!I65-SUM('Data Sheet'!I67,'Data Sheet'!I68,'Data Sheet'!I69),0) -> 444.07 | ... M55: =IFERROR('Data Sheet'!L65-SUM('Data Sheet'!L67,'Data Sheet'!L68,'Data Sheet'!L69),0) -> 0
B56: Total non Current assets | C56: =IFERROR(SUM(C52,C53,C54,C55),0) -> 1883.42 | D56: =IFERROR(SUM(D52,D53,D54,D55),0) -> 2048.37 | E56: =IFERROR(SUM(E52,E53,E54,E55),0) -> 2497.51 | F56: =IFERROR(SUM(F52,F53,F54,F55),0) -> 2675.2 | G56: =IFERROR(SUM(G52,G53,G54,G55),0) -> 3073.86 | H56: =IFERROR(SUM(H52,H53,H54,H55),0) -> 4180.67 | I56: =IFERROR(SUM(I52,I53,I54,I55),0) -> 7196.72 | J56: =IFERROR(SUM(J52,J53,J54,J55),0) -> 7215.59 | ... M56: =IFERROR(SUM(M52,M53,M54,M55),0) -> 0
...

Sheet RATIO ANALYSIS
E1: ="RATIO ANALYSIS OF - "&'Data Sheet'!B1 -> RATIO ANALYSIS OF - ESCORTS KUBOTA LTD
A2: YEARS | B2: ='Data Sheet'!B16 -> 42460 | C2: ='Data Sheet'!C16 -> 42825 | D2: ='Data Sheet'!D16 -> 43190 | E2: ='Data Sheet'!E16 -> 43555 | F2: ='Data Sheet'!F16 -> 43921 | G2: ='Data Sheet'!G16 -> 44286 | H2: ='Data Sheet'!H16 -> 44651 | I2: ='Data Sheet'!I16 -> 45016 | ... K2: ='Data Sheet'!K16 -> 45747 | L2: TREND LINE | M2: MEAN | N2: MEDIAN
A4: Sales Growth | B4: =IFERROR('HISTORICAL FS'!C6,0) -> - | C4: =IFERROR('HISTORICAL FS'!D6,0) -> 0.20785026 | D4: =IFERROR('HISTORICAL FS'!E6,0) -> 0.22049149 | E4: =IFERROR('HISTORICAL FS'!F6,0) -> 0.2377148 | F4: =IFERROR('HISTORICAL FS'!G6,0) -> -0.072170003 | G4: =IFERROR('HISTORICAL FS'!H6,0) -> 0.2072825 | H4: =IFERROR('HISTORICAL FS'!I6,0) -> 0.038239797 | I4: =IFERROR('HISTORICAL FS'!J6,0) -> 0.15736579 | ... K4: =IFERROR('HISTORICAL FS'!L6,0) -> 0.044911099 | M4: =IFERROR(AVERAGE(C4:K4),0) -> 0.13386746 | N4: =IFERROR(MEDIAN(C4:K4),0) -> 0.16312143
A5: EBITDA Growth | B5: - | C5: =IFERROR('HISTORICAL FS'!E17/'HISTORICAL FS'!D17-1,0) -> 1.0664351 | D5: =IFERROR('HISTORICAL FS'!F17/'HISTORICAL FS'!E17-1,0) -> 0.30581007 | E5: =IFERROR('HISTORICAL FS'!G17/'HISTORICAL FS'!F17-1,0) -> -0.084766874 | F5: =IFERROR('HISTORICAL FS'!H17/'HISTORICAL FS'!G17-1,0) -> 0.70268554 | G5: =IFERROR('HISTORICAL FS'!I17/'HISTORICAL FS'!H17-1,0) -> -0.14205787 | H5: =IFERROR('HISTORICAL FS'!J17/'HISTORICAL FS'!I17-1,0) -> -0.20290665 | I5: =IFERROR('HISTORICAL FS'!K17/'HISTORICAL FS'!J17-1,0) -> 0.46793673 | J5: =IFERROR('HISTORICAL FS'!L17/'HISTORICAL FS'!K17-1,0) -> 0.029919407 | K5: =IFERROR('HISTORICAL FS'!M17/'HISTORICAL FS'!L17-1,0) -> 0.04514727 | M5: =IFERROR(AVERAGE(C5:K5),0) -> 0.24313364 | N5: =IFERROR(MEDIAN(C5:K5),0) -> 0.04514727
A6: EBIT Growth | B6: - | C6: =IFERROR('HISTORICAL FS'!E26/'HISTORICAL FS'!D26-1,0) -> 1.6177171 | D6: =IFERROR('HISTORICAL FS'!F26/'HISTORICAL FS'!E26-1,0) -> 0.36654536 | E6: =IFERROR('HISTORICAL FS'!G26/'HISTORICAL FS'!F26-1,0) -> -0.12820305 | F6: =IFERROR('HISTORICAL FS'!H26/'HISTORICAL FS'!G26-1,0) -> 0.85221748 | G6: =IFERROR('HISTORICAL FS'!I26/'HISTORICAL FS'!H26-1,0) -> -0.1763576 | H6: =IFERROR('HISTORICAL FS'!J26/'HISTORICAL FS'!I26-1,0) -> -0.25923348 | I6: =IFERROR('HISTORICAL FS'!K26/'HISTORICAL FS'!J26-1,0) -> 0.42514546 | J6: =IFERROR('HISTORICAL FS'!L26/'HISTORICAL FS'!K26-1,0) -> 0.030902677 | K6: =IFERROR('HISTORICAL FS'!M26/'HISTORICAL FS'!L26-1,0) -> 0.056070992 | M6: =IFERROR(AVERAGE(C6:K6),0) -> 0.30942277 | N6: =IFERROR(MEDIAN(C6:K6),0) -> 0.056070992
A7: Net profit Growth | B7: - | C7: =IFERROR('HISTORICAL FS'!E32/'HISTORICAL FS'!D32-1,0) -> 2.0363541 | D7: =IFERROR('HISTORICAL FS'!F32/'HISTORICAL FS'!E32-1,0) -> 0.31428076 | E7: =IFERROR('HISTORICAL FS'!G32/'HISTORICAL FS'!F32-1,0) -> 0.012225714 | F7: =IFERROR('HISTORICAL FS'!H32/'HISTORICAL FS'!G32-1,0) -> 0.85540251 | G7: =IFERROR('HISTORICAL FS'!I32/'HISTORICAL FS'!H32-1,0) -> -0.21010896 | H7: =IFERROR('HISTORICAL FS'!J32/'HISTORICAL FS'!I32-1,0) -> -0.27240526 | I7: =IFERROR('HISTORICAL FS'!K32/'HISTORICAL FS'!J32-1,0) -> 0.34855787 | J7: =IFERROR('HISTORICAL FS'!L32/'HISTORICAL FS'!K32-1,0) -> 0.20529705 | K7: =IFERROR('HISTORICAL FS'!M32/'HISTORICAL FS'!L32-1,0) -> 0.056048885 | M7: =IFERROR(AVERAGE(C7:K7),0) -> 0.37173918 | N7: =IFERROR(MEDIAN(C7:K7),0) -> 0.20529705
A8: Dividend Growth | B8: - | C8: =IFERROR('HISTORICAL FS'!D40/'HISTORICAL FS'!C40-1,0) -> 0.25016995 | D8: =IFERROR('HISTORICAL FS'!E40/'HISTORICAL FS'!D40-1,0) -> 0.33333333 | E8: =IFERROR('HISTORICAL FS'!F40/'HISTORICAL FS'!E40-1,0) -> 0.24959217 | F8: =IFERROR('HISTORICAL FS'!G40/'HISTORICAL FS'!F40-1,0) -> 0 | G8: =IFERROR('HISTORICAL FS'!H40/'HISTORICAL FS'!G40-1,0) -> 2.0015728 | H8: =IFERROR('HISTORICAL FS'!I40/'HISTORICAL FS'!H40-1,0) -> -0.066548066 | I8: =IFERROR('HISTORICAL FS'!J40/'HISTORICAL FS'!I40-1,0) -> 0 | J8: =IFERROR('HISTORICAL FS'!K40/'HISTORICAL FS'!J40-1,0) -> 1.5705933 | K8: =IFERROR('HISTORICAL FS'!L40/'HISTORICAL FS'!K40-1,0) -> 0.55525767 | M8: =IFERROR(AVERAGE(C8:K8),0) -> 0.54377457 | N8: =IFERROR(MEDIAN(C8:K8),0) -> 0.25016995
A10: Gross Margin | B10: =IFERROR('HISTORICAL FS'!C12,0) -> 0.14557735 | C10: =IFERROR('HISTORICAL FS'!D12,0) -> 0.17256768 | D10: =IFERROR('HISTORICAL FS'!E12,0) -> 0.19485546 | E10: =IFERROR('HISTORICAL FS'!F12,0) -> 0.19665539 | F10: =IFERROR('HISTORICAL FS'!G12,0) -> 0.20597443 | G10: =IFERROR('HISTORICAL FS'!H12,0) -> 0.22400427 | H10: =IFERROR('HISTORICAL FS'!I12,0) -> 0.20346028 | I10: =IFERROR('HISTORICAL FS'!J12,0) -> 0.16093723 | ... K10: =IFERROR('HISTORICAL FS'!L12,0) -> 0.17338059 | M10: =IFERROR(AVERAGE(B10:K10),0) -> 0.18545774 | N10: =IFERROR(AVERAGE(C10:L10),0) -> 0.18988889
A11: EBITDA Margin | B11: =IFERROR('HISTORICAL FS'!C18,0) -> 0.04689699 | C11: =IFERROR('HISTORICAL FS'!D18,0) -> 0.064597993 | D11: =IFERROR('HISTORICAL FS'!E18,0) -> 0.10937197 | E11: =IFERROR('HISTORICAL FS'!F18,0) -> 0.11538928 | F11: =IFERROR('HISTORICAL FS'!G18,0) -> 0.11382268 | G11: =IFERROR('HISTORICAL FS'!H18,0) -> 0.16052931 | H11: =IFERROR('HISTORICAL FS'!I18,0) -> 0.13265226 | I11: =IFERROR('HISTORICAL FS'!J18,0) -> 0.091359393 | ... K11: =IFERROR('HISTORICAL FS'!L18,0) -> 0.11364737 | M11: =IFERROR(AVERAGE(B11:K11),0) -> 0.10635689 | N11: =IFERROR(AVERAGE(C11:L11),0) -> 0.11296354
A12: EBIT Margin | B12: =IFERROR(('HISTORICAL FS'!C17-'HISTORICAL FS'!C23)/'HISTORICAL FS'!C5,0) -> 0.029959295 | C12: =IFERROR(('HISTORICAL FS'!D17-'HISTORICAL FS'!D23)/'HISTORICAL FS'!D5,0) -> 0.04929885 | D12: =IFERROR(('HISTORICAL FS'!E17-'HISTORICAL FS'!E23)/'HISTORICAL FS'!E5,0) -> 0.09489973 | E12: =IFERROR(('HISTORICAL FS'!F17-'HISTORICAL FS'!F23)/'HISTORICAL FS'!F5,0) -> 0.10146247 | F12: =IFERROR(('HISTORICAL FS'!G17-'HISTORICAL FS'!G23)/'HISTORICAL FS'!G5,0) -> 0.095368574 | G12: =IFERROR(('HISTORICAL FS'!H17-'HISTORICAL FS'!H23)/'HISTORICAL FS'!H5,0) -> 0.1436669 | H12: =IFERROR(('HISTORICAL FS'!I17-'HISTORICAL FS'!I23)/'HISTORICAL FS'!I5,0) -> 0.11451875 | I12: =IFERROR(('HISTORICAL FS'!J17-'HISTORICAL FS'!J23)/'HISTORICAL FS'!J5,0) -> 0.073555914 | ... K12: =IFERROR(('HISTORICAL FS'!L17-'HISTORICAL FS'!L23)/'HISTORICAL FS'!L5,0) -> 0.089862435 | M12: =IFERROR(AVERAGE(B12:K12),0) -> 0.088503967 | N12: =IFERROR(AVERAGE(C12:L12),0) -> 0.09500893
A13: EBT Margin | B13: =IFERROR('HISTORICAL FS'!C27,0) -> 0.015081629 | C13: =IFERROR('HISTORICAL FS'!D27,0) -> 0.04152866 | D13: =IFERROR('HISTORICAL FS'!E27,0) -> 0.089070906 | E13: =IFERROR('HISTORICAL FS'!F27,0) -> 0.098342069 | F13: =IFERROR('HISTORICAL FS'!G27,0) -> 0.092403044 | G13: =IFERROR('HISTORICAL FS'!H27,0) -> 0.14176511 | H13: =IFERROR('HISTORICAL FS'!I27,0) -> 0.11246318 | I13: =IFERROR('HISTORICAL FS'!J27,0) -> 0.07198153 | ... K13: =IFERROR('HISTORICAL FS'!L27,0) -> 0.087014881 | M13: =IFERROR(AVERAGE(B13:K13),0) -> 0.083784829 | N13: =IFERROR(AVERAGE(C13:L13),0) -> 0.091418518
A14: Net profit margin | B14: =IFERROR('HISTORICAL FS'!C33,0) -> 0.011506444 | C14: =IFERROR('HISTORICAL FS'!D33,0) -> 0.022893232 | D14: =IFERROR('HISTORICAL FS'!E33,0) -> 0.056954069 | E14: =IFERROR('HISTORICAL FS'!F33,0) -> 0.06047729 | F14: =IFERROR('HISTORICAL FS'!G33,0) -> 0.065978324 | G14: =IFERROR('HISTORICAL FS'!H33,0) -> 0.10139826 | H14: =IFERROR('HISTORICAL FS'!I33,0) -> 0.077143622 | I14: =IFERROR('HISTORICAL FS'!J33,0) -> 0.048497453 | ... K14: =IFERROR('HISTORICAL FS'!L33,0) -> 0.06486019 | M14: =IFERROR(AVERAGE(B14:K14),0) -> 0.056593829 | N14: =IFERROR(AVERAGE(C14:L14),0) -> 0.061603538
A16: Sales expenses % Sales | B16: =IFERROR('HISTORICAL FS'!C15,0) -> 0.098680357 | C16: =IFERROR('HISTORICAL FS'!D15,0) -> 0.10796969 | D16: =IFERROR('HISTORICAL FS'!E15,0) -> 0.085483482 | E16: =IFERROR('HISTORICAL FS'!F15,0) -> 0.081266109 | F16: =IFERROR('HISTORICAL FS'!G15,0) -> 0.092151757 | G16: =IFERROR('HISTORICAL FS'!H15,0) -> 0.063474956 | H16: =IFERROR('HISTORICAL FS'!I15,0) -> 0.070808016 | I16: =IFERROR('HISTORICAL FS'!J15,0) -> 0.069577835 | ... K16: =IFERROR('HISTORICAL FS'!L15,0) -> 0.059733226 | M16: =IFERROR(AVERAGE(B16:K16),0) -> 0.079100848 | N16: =IFERROR(AVERAGE(C16:L16),0) -> 0.076925347
A17: Deprication% Sales | B17: =IFERROR('HISTORICAL FS'!C24,0) -> 0.016937695 | C17: =IFERROR('HISTORICAL FS'!D24,0) -> 0.015299144 | D17: =IFERROR('HISTORICAL FS'!E24,0) -> 0.014472243 | E17: =IFERROR('HISTORICAL FS'!F24,0) -> 0.013926816 | F17: =IFERROR('HISTORICAL FS'!G24,0) -> 0.018454103 | G17: =IFERROR('HISTORICAL FS'!H24,0) -> 0.016862406 | H17: =IFERROR('HISTORICAL FS'!I24,0) -> 0.018133509 | I17: =IFERROR('HISTORICAL FS'!J24,0) -> 0.017803478 | ... K17: =IFERROR('HISTORICAL FS'!L24,0) -> 0.023784933 | M17: =IFERROR(AVERAGE(B17:K17),0) -> 0.017852922 | N17: =IFERROR(AVERAGE(C17:L17),0) -> 0.017954614
A18: Opearting income sales% | B18: =IFERROR(B12,0) -> 0.029959295 | C18: =IFERROR(C12,0) -> 0.04929885 | D18: =IFERROR(D12,0) -> 0.09489973 | E18: =IFERROR(E12,0) -> 0.10146247 | F18: =IFERROR(F12,0) -> 0.095368574 | G18: =IFERROR(G12,0) -> 0.1436669 | H18: =IFERROR(H12,0) -> 0.11451875 | I18: =IFERROR(I12,0) -> 0.073555914 | ... K18: =IFERROR(K12,0) -> 0.089862435 | M18: =IFERROR(AVERAGE(B18:K18),0) -> 0.088503967 | N18: =IFERROR(AVERAGE(C18:L18),0) -> 0.09500893
A20: Return on capital employed | B20: =IFERROR(('HISTORICAL FS'!C17-'HISTORICAL FS'!C23)/(SUM('HISTORICAL FS'!C46,'HISTORICAL FS'!C47,'HISTORICAL FS'!C48)),0) -> 0.056044914 | C20: =IFERROR(('HISTORICAL FS'!D17-'HISTORICAL FS'!D23)/(SUM('HISTORICAL FS'!D46,'HISTORICAL FS'!D47,'HISTORICAL FS'!D48)),0) -> 0.10833563 | D20: =IFERROR(('HISTORICAL FS'!E17-'HISTORICAL FS'!E23)/(SUM('HISTORICAL FS'!E46,'HISTORICAL FS'!E47,'HISTORICAL FS'!E48)),0) -> 0.21186287 | E20: =IFERROR(('HISTORICAL FS'!F17-'HISTORICAL FS'!F23)/(SUM('HISTORICAL FS'!F46,'HISTORICAL FS'!F47,'HISTORICAL FS'!F48)),0) -> 0.21505187 | F20: =IFERROR(('HISTORICAL FS'!G17-'HISTORICAL FS'!G23)/(SUM('HISTORICAL FS'!G46,'HISTORICAL FS'!G47,'HISTORICAL FS'!G48)),0) -> 0.17506722 | G20: =IFERROR(('HISTORICAL FS'!H17-'HISTORICAL FS'!H23)/(SUM('HISTORICAL FS'!H46,'HISTORICAL FS'!H47,'HISTORICAL FS'!H48)),0) -> 0.19811117 | H20: =IFERROR(('HISTORICAL FS'!I17-'HISTORICAL FS'!I23)/(SUM('HISTORICAL FS'!I46,'HISTORICAL FS'!I47,'HISTORICAL FS'!I48)),0) -> 0.10899325 | I20: =IFERROR(('HISTORICAL FS'!J17-'HISTORICAL FS'!J23)/(SUM('HISTORICAL FS'!J46,'HISTORICAL FS'!J47,'HISTORICAL FS'!J48)),0) -> 0.075203693 | ... K20: =IFERROR(('HISTORICAL FS'!L17-'HISTORICAL FS'!L23)/(SUM('HISTORICAL FS'!L46,'HISTORICAL FS'!L47,'HISTORICAL FS'!L48)),0) -> 0.087905057 | M20: =IFERROR(AVERAGE(B20:K20),0) -> 0.13287087 | N20: =IFERROR(AVERAGE(C20:L20),0) -> 0.14140709
A21: Retained earnings % | B21: =IFERROR('HISTORICAL FS'!C43,0) -> 0.62750063 | C21: =IFERROR('HISTORICAL FS'!D43,0) -> 0.80621707 | D21: =IFERROR('HISTORICAL FS'!E43,0) -> 0.91490543 | E21: =IFERROR('HISTORICAL FS'!F43,0) -> 0.91909377 | F21: =IFERROR('HISTORICAL FS'!G43,0) -> 0.92007096 | G21: =IFERROR('HISTORICAL FS'!H43,0) -> 0.85782777 | H21: =IFERROR('HISTORICAL FS'!I43,0) -> 0.83560278 | I21: =IFERROR('HISTORICAL FS'!J43,0) -> 0.77405387 | ... K21: =IFERROR('HISTORICAL FS'!L43,0) -> 0.52852112 | M21: =IFERROR(AVERAGE(B21:K21),0) -> 0.78229771 | N21: =IFERROR(AVERAGE(C21:L21),0) -> 0.79949738
A22: Return on equity % | B22: =IFERROR('HISTORICAL FS'!C32/ SUM('HISTORICAL FS'!C46,'HISTORICAL FS'!C47),0) -> 0.026928427 | C22: =IFERROR('HISTORICAL FS'!D32/ SUM('HISTORICAL FS'!D46,'HISTORICAL FS'!D47),0) -> 0.058546637 | D22: =IFERROR('HISTORICAL FS'!E32/ SUM('HISTORICAL FS'!E46,'HISTORICAL FS'!E47),0) -> 0.13008207 | E22: =IFERROR('HISTORICAL FS'!F32/ SUM('HISTORICAL FS'!F46,'HISTORICAL FS'!F47),0) -> 0.14165379 | F22: =IFERROR('HISTORICAL FS'!G32/ SUM('HISTORICAL FS'!G46,'HISTORICAL FS'!G47),0) -> 0.12296786 | G22: =IFERROR('HISTORICAL FS'!H32/ SUM('HISTORICAL FS'!H46,'HISTORICAL FS'!H47),0) -> 0.14151047 | H22: =IFERROR('HISTORICAL FS'!I32/ SUM('HISTORICAL FS'!I46,'HISTORICAL FS'!I47),0) -> 0.073923341 | I22: =IFERROR('HISTORICAL FS'!J32/ SUM('HISTORICAL FS'!J46,'HISTORICAL FS'!J47),0) -> 0.049930925 | ... K22: =IFERROR('HISTORICAL FS'!L32/ SUM('HISTORICAL FS'!L46,'HISTORICAL FS'!L47),0) -> 0.064091137 | M22: =IFERROR(AVERAGE(B22:K22),0) -> 0.086835004 | N22: =IFERROR(AVERAGE(C22:L22),0) -> 0.093491291
A23: Self sustained growth rate | B23: =IFERROR(B21*B22,0) -> 0.016897605 | C23: =IFERROR(C21*C22,0) -> 0.047201298 | D23: =IFERROR(D21*D22,0) -> 0.11901279 | E23: =IFERROR(E21*E22,0) -> 0.13019312 | F23: =IFERROR(F21*F22,0) -> 0.11313915 | G23: =IFERROR(G21*G22,0) -> 0.12139161 | H23: =IFERROR(H21*H22,0) -> 0.06177055 | I23: =IFERROR(I21*I22,0) -> 0.038649225 | ... K23: =IFERROR(K21*K22,0) -> 0.033873519 | M23: =IFERROR(AVERAGE(B23:K23),0) -> 0.071965879 | N23: =IFERROR(AVERAGE(C23:L23),0) -> 0.078084576
A24: Interest coverage ratio | B24: =IFERROR(('HISTORICAL FS'!C17-'HISTORICAL FS'!C23)/'HISTORICAL FS'!C20,0) -> 2.0137094 | C24: =IFERROR(('HISTORICAL FS'!D17-'HISTORICAL FS'!D23)/'HISTORICAL FS'!D20,0) -> 6.3446135 | D24: =IFERROR(('HISTORICAL FS'!E17-'HISTORICAL FS'!E23)/'HISTORICAL FS'!E20,0) -> 16.281112 | E24: =IFERROR(('HISTORICAL FS'!F17-'HISTORICAL FS'!F23)/'HISTORICAL FS'!F20,0) -> 32.515865 | F24: =IFERROR(('HISTORICAL FS'!G17-'HISTORICAL FS'!G23)/'HISTORICAL FS'!G20,0) -> 32.159025 | G24: =IFERROR(('HISTORICAL FS'!H17-'HISTORICAL FS'!H23)/'HISTORICAL FS'!H20,0) -> 75.542729 | H24: =IFERROR(('HISTORICAL FS'!I17-'HISTORICAL FS'!I23)/'HISTORICAL FS'!I20,0) -> 55.711423 | I24: =IFERROR(('HISTORICAL FS'!J17-'HISTORICAL FS'!J23)/'HISTORICAL FS'!J20,0) -> 46.720422 | ... K24: =IFERROR(('HISTORICAL FS'!L17-'HISTORICAL FS'!L23)/'HISTORICAL FS'!L20,0) -> 31.557765 | M24: =IFERROR(AVERAGE(B24:K24),0) -> 32.060158 | N24: =IFERROR(AVERAGE(C24:L24),0) -> 35.398653
A26: TURNOVER RATIO
A27: Debtor Turnover ratio | B27: =IFERROR('HISTORICAL FS'!C5/'HISTORICAL FS'!C58,0) -> 9.1527055 | C27: =IFERROR('HISTORICAL FS'!D5/'HISTORICAL FS'!D58,0) -> 9.0816738 | D27: =IFERROR('HISTORICAL FS'!E5/'HISTORICAL FS'!E58,0) -> 8.5461824 | E27: =IFERROR('HISTORICAL FS'!F5/'HISTORICAL FS'!F58,0) -> 6.7257612 | F27: =IFERROR('HISTORICAL FS'!G5/'HISTORICAL FS'!G58,0) -> 7.9387998 | G27: =IFERROR('HISTORICAL FS'!H5/'HISTORICAL FS'!H58,0) -> 10.667022 | H27: =IFERROR('HISTORICAL FS'!I5/'HISTORICAL FS'!I58,0) -> 9.1880725 | I27: =IFERROR('HISTORICAL FS'!J5/'HISTORICAL FS'!J58,0) -> 7.1450769 | ... K27: =IFERROR('HISTORICAL FS'!L5/'HISTORICAL FS'!L58,0) -> 7.6915245 | M27: =IFERROR(AVERAGE(B27:K27),0) -> 8.300251 | N27: =IFERROR(AVERAGE(C27:L27),0) -> 8.2055338
A28: Credot turnover ratio | B28: =IFERROR('HISTORICAL FS'!C5/'HISTORICAL FS'!C49,0) -> 3.0275675 | C28: =IFERROR('HISTORICAL FS'!D5/'HISTORICAL FS'!D49,0) -> 3.1574806 | D28: =IFERROR('HISTORICAL FS'!E5/'HISTORICAL FS'!E49,0) -> 2.9650941 | E28: =IFERROR('HISTORICAL FS'!F5/'HISTORICAL FS'!F49,0) -> 3.5731518 | F28: =IFERROR('HISTORICAL FS'!G5/'HISTORICAL FS'!G49,0) -> 3.1424747 | G28: =IFERROR('HISTORICAL FS'!H5/'HISTORICAL FS'!H49,0) -> 3.9155423 | H28: =IFERROR('HISTORICAL FS'!I5/'HISTORICAL FS'!I49,0) -> 5.002198 | I28: =IFERROR('HISTORICAL FS'!J5/'HISTORICAL FS'!J49,0) -> 4.5787941 | ... K28: =IFERROR('HISTORICAL FS'!L5/'HISTORICAL FS'!L49,0) -> 3.9058379 | M28: =IFERROR(AVERAGE(B28:K28),0) -> 3.7092604 | N28: =IFERROR(AVERAGE(C28:L28),0) -> 3.785004
A29: Inventory turnover | B29: =IFERROR('HISTORICAL FS'!C5/'HISTORICAL FS'!C59,0) -> 7.5137709 | C29: =IFERROR('HISTORICAL FS'!D5/'HISTORICAL FS'!D59,0) -> 9.2057073 | D29: =IFERROR('HISTORICAL FS'!E5/'HISTORICAL FS'!E59,0) -> 8.9430294 | E29: =IFERROR('HISTORICAL FS'!F5/'HISTORICAL FS'!F59,0) -> 7.3033286 | F29: =IFERROR('HISTORICAL FS'!G5/'HISTORICAL FS'!G59,0) -> 6.5772618 | G29: =IFERROR('HISTORICAL FS'!H5/'HISTORICAL FS'!H59,0) -> 9.7672106 | H29: =IFERROR('HISTORICAL FS'!I5/'HISTORICAL FS'!I59,0) -> 8.6026389 | I29: =IFERROR('HISTORICAL FS'!J5/'HISTORICAL FS'!J59,0) -> 6.9219253 | ... K29: =IFERROR('HISTORICAL FS'!L5/'HISTORICAL FS'!L59,0) -> 7.3223397 | M29: =IFERROR(AVERAGE(B29:K29),0) -> 7.7869728 | N29: =IFERROR(AVERAGE(C29:L29),0) -> 7.8173285
A30: Fixed asset turnover | B30: =IFERROR('HISTORICAL FS'!C5/'HISTORICAL FS'!C52,0) -> 2.229984 | C30: =IFERROR('HISTORICAL FS'!D5/'HISTORICAL FS'!D52,0) -> 2.621735 | D30: =IFERROR('HISTORICAL FS'!E5/'HISTORICAL FS'!E52,0) -> 3.1863837 | E30: =IFERROR('HISTORICAL FS'!F5/'HISTORICAL FS'!F52,0) -> 3.8015456 | F30: =IFERROR('HISTORICAL FS'!G5/'HISTORICAL FS'!G52,0) -> 3.4128618 | G30: =IFERROR('HISTORICAL FS'!H5/'HISTORICAL FS'!H52,0) -> 3.905079 | H30: =IFERROR('HISTORICAL FS'!I5/'HISTORICAL FS'!I52,0) -> 3.9557046 | I30: =IFERROR('HISTORICAL FS'!J5/'HISTORICAL FS'!J52,0) -> 4.4569125 | ... K30: =IFERROR('HISTORICAL FS'!L5/'HISTORICAL FS'!L52,0) -> 4.9892752 | M30: =IFERROR(AVERAGE(B30:K30),0) -> 3.7087113 | N30: =IFERROR(AVERAGE(C30:L30),0) -> 3.8730143
A31: Capital turnover | B31: =IFERROR('HISTORICAL FS'!C5/SUM('HISTORICAL FS'!C46,'HISTORICAL FS'!C47),0) -> 2.340291 | C31: =IFERROR('HISTORICAL FS'!D5/SUM('HISTORICAL FS'!D46,'HISTORICAL FS'!D47),0) -> 2.5573776 | D31: =IFERROR('HISTORICAL FS'!E5/SUM('HISTORICAL FS'!E46,'HISTORICAL FS'!E47),0) -> 2.2839821 | E31: =IFERROR('HISTORICAL FS'!F5/SUM('HISTORICAL FS'!F46,'HISTORICAL FS'!F47),0) -> 2.3422642 | F31: =IFERROR('HISTORICAL FS'!G5/SUM('HISTORICAL FS'!G46,'HISTORICAL FS'!G47),0) -> 1.8637615 | G31: =IFERROR('HISTORICAL FS'!H5/SUM('HISTORICAL FS'!H46,'HISTORICAL FS'!H47),0) -> 1.3955906 | H31: =IFERROR('HISTORICAL FS'!I5/SUM('HISTORICAL FS'!I46,'HISTORICAL FS'!I47),0) -> 0.95825603 | I31: =IFERROR('HISTORICAL FS'!J5/SUM('HISTORICAL FS'!J46,'HISTORICAL FS'!J47),0) -> 1.0295577 | ... K31: =IFERROR('HISTORICAL FS'!L5/SUM('HISTORICAL FS'!L46,'HISTORICAL FS'!L47),0) -> 0.98814292 | M31: =IFERROR(AVERAGE(B31:K31),0) -> 1.6803435 | N31: =IFERROR(AVERAGE(C31:L31),0) -> 1.607016
A33: Debtor days | B33: =IFERROR(365/B27,0) -> 39.878919 | C33: =IFERROR(365/C27,0) -> 40.190829 | D33: =IFERROR(365/D27,0) -> 42.709128 | E33: =IFERROR(365/E27,0) -> 54.26895 | F33: =IFERROR(365/F27,0) -> 45.976723 | G33: =IFERROR(365/G27,0) -> 34.217612 | H33: =IFERROR(365/H27,0) -> 39.725416 | I33: =IFERROR(365/I27,0) -> 51.084125 | ... K33: =IFERROR(365/K27,0) -> 47.454832 | M33: =IFERROR(AVERAGE(B33:K33),0) -> 44.866942 | N33: =IFERROR(AVERAGE(C33:L33),0) -> 45.421167
A34: Payable days | B34: =IFERROR(365/B28,0) -> 120.55883 | C34: =IFERROR(365/C28,0) -> 115.59849 | D34: =IFERROR(365/D28,0) -> 123.09896 | E34: =IFERROR(365/E28,0) -> 102.15071 | F34: =IFERROR(365/F28,0) -> 116.1505 | G34: =IFERROR(365/G28,0) -> 93.218249 | H34: =IFERROR(365/H28,0) -> 72.967924 | I34: =IFERROR(365/I28,0) -> 79.715312 | ... K34: =IFERROR(365/K28,0) -> 93.44986 | M34: =IFERROR(AVERAGE(B34:K34),0) -> 101.23471 | N34: =IFERROR(AVERAGE(C34:L34),0) -> 99.087583
A35: Inventory days | B35: =IFERROR(365/B29,0) -> 48.577473 | C35: =IFERROR(365/C29,0) -> 39.649316 | D35: =IFERROR(365/D29,0) -> 40.813911 | E35: =IFERROR(365/E29,0) -> 49.977212 | F35: =IFERROR(365/F29,0) -> 55.494218 | G35: =IFERROR(365/G29,0) -> 37.369932 | H35: =IFERROR(365/H29,0) -> 42.428841 | I35: =IFERROR(365/I29,0) -> 52.730994 | ... K35: =IFERROR(365/K29,0) -> 49.847455 | M35: =IFERROR(AVERAGE(B35:K35),0) -> 48.078415 | N35: =IFERROR(AVERAGE(C35:L35),0) -> 48.022964
A36: Cash conversion cycle | B36: =IFERROR(B33+B35-B34,0) -> -32.102439 | C36: =IFERROR(C33+C35-C34,0) -> -35.758347 | D36: =IFERROR(D33+D35-D34,0) -> -39.575923 | E36: =IFERROR(E33+E35-E34,0) -> 2.09545 | F36: =IFERROR(F33+F35-F34,0) -> -14.679557 | G36: =IFERROR(G33+G35-G34,0) -> -21.630705 | H36: =IFERROR(H33+H35-H34,0) -> 9.1863333 | I36: =IFERROR(I33+I35-I34,0) -> 24.099807 | ... K36: =IFERROR(K33+K35-K34,0) -> 3.852427 | M36: =IFERROR(AVERAGE(B36:K36),0) -> -8.2893507 | N36: =IFERROR(AVERAGE(C36:L36),0) -> -5.643452
A38: CFO/Sales | B38: =IFERROR('HISTORICAL FS'!C76/'HISTORICAL FS'!C5,0) -> 0.072844035 | C38: =IFERROR('HISTORICAL FS'!D76/'HISTORICAL FS'!D5,0) -> 0.092875597 | D38: =IFERROR('HISTORICAL FS'!E76/'HISTORICAL FS'!E5,0) -> 0.11266292 | E38: =IFERROR('HISTORICAL FS'!F76/'HISTORICAL FS'!F5,0) -> -0.12392167 | F38: =IFERROR('HISTORICAL FS'!G76/'HISTORICAL FS'!G5,0) -> 0.22960057 | G38: =IFERROR('HISTORICAL FS'!H76/'HISTORICAL FS'!H5,0) -> 0.23280613 | H38: =IFERROR('HISTORICAL FS'!I76/'HISTORICAL FS'!I5,0) -> -0.047647491 | I38: =IFERROR('HISTORICAL FS'!J76/'HISTORICAL FS'!J5,0) -> 0.0036779144 | ... K38: =IFERROR('HISTORICAL FS'!L76/'HISTORICAL FS'!L5,0) -> 0.16751465 | M38: =IFERROR(AVERAGE(B38:K38),0) -> 0.081181507 | N38: =IFERROR(AVERAGE(C38:L38),0) -> 0.082107893
A39: CFO/Total assets | B39: =IFERROR('HISTORICAL FS'!C76/'HISTORICAL FS'!C63,0) -> 0.084226698 | C39: =IFERROR('HISTORICAL FS'!D76/'HISTORICAL FS'!D63,0) -> 0.12034183 | D39: =IFERROR('HISTORICAL FS'!E76/'HISTORICAL FS'!E63,0) -> 0.14348539 | E39: =IFERROR('HISTORICAL FS'!F76/'HISTORICAL FS'!F63,0) -> -0.1648619 | F39: =IFERROR('HISTORICAL FS'!G76/'HISTORICAL FS'!G63,0) -> 0.26605717 | G39: =IFERROR('HISTORICAL FS'!H76/'HISTORICAL FS'!H63,0) -> 0.2374178 | H39: =IFERROR('HISTORICAL FS'!I76/'HISTORICAL FS'!I63,0) -> -0.038099463 | I39: =IFERROR('HISTORICAL FS'!J76/'HISTORICAL FS'!J63,0) -> 0.003073927 | ... K39: =IFERROR('HISTORICAL FS'!L76/'HISTORICAL FS'!L63,0) -> 0.13104548 | M39: =IFERROR(AVERAGE(B39:K39),0) -> 0.083913691 | N39: =IFERROR(AVERAGE(C39:L39),0) -> 0.083878913
A40: CFO/Total debt | B40: =IFERROR('HISTORICAL FS'!C76/'HISTORICAL FS'!C48,0) -> 0.67912637 | C40: =IFERROR('HISTORICAL FS'!D76/'HISTORICAL FS'!D48,0) -> 1.4504766 | D40: =IFERROR('HISTORICAL FS'!E76/'HISTORICAL FS'!E48,0) -> 11.156782 | E40: =IFERROR('HISTORICAL FS'!F76/'HISTORICAL FS'!F48,0) -> -2.761959 | F40: =IFERROR('HISTORICAL FS'!G76/'HISTORICAL FS'!G48,0) -> 27.984057 | G40: =IFERROR('HISTORICAL FS'!H76/'HISTORICAL FS'!H48,0) -> 26.942749 | H40: =IFERROR('HISTORICAL FS'!I76/'HISTORICAL FS'!I48,0) -> -6.6794995 | I40: =IFERROR('HISTORICAL FS'!J76/'HISTORICAL FS'!J48,0) -> 0.54101222 | ... K40: =IFERROR('HISTORICAL FS'!L76/'HISTORICAL FS'!L48,0) -> 16.314889 | M40: =IFERROR(AVERAGE(B40:K40),0) -> 7.7188531 | N40: =IFERROR(AVERAGE(C40:L40),0) -> 8.5010449
A42: RETURN ON ASSETS
A43: PAT vs TOTAL ASSETS | B43: =IFERROR('HISTORICAL FS'!C32/'HISTORICAL FS'!C63,0) -> 0.013304449 | C43: =IFERROR('HISTORICAL FS'!D32/'HISTORICAL FS'!D63,0) -> 0.02966348 | D43: =IFERROR('HISTORICAL FS'!E32/'HISTORICAL FS'!E63,0) -> 0.072535638 | E43: =IFERROR('HISTORICAL FS'!F32/'HISTORICAL FS'!F63,0) -> 0.080457279 | F43: =IFERROR('HISTORICAL FS'!G32/'HISTORICAL FS'!G63,0) -> 0.076454539 | G43: =IFERROR('HISTORICAL FS'!H32/'HISTORICAL FS'!H63,0) -> 0.10340687 | H43: =IFERROR('HISTORICAL FS'!I32/'HISTORICAL FS'!I63,0) -> 0.061684897 | I43: =IFERROR('HISTORICAL FS'!J32/'HISTORICAL FS'!J63,0) -> 0.040533197 | ... K43: =IFERROR('HISTORICAL FS'!L32/'HISTORICAL FS'!L63,0) -> 0.050739651 | M43: =IFERROR(AVERAGE(B43:K43),0) -> 0.057323435 | N43: =IFERROR(AVERAGE(C43:L43),0) -> 0.062214434
A44: EBIT vs TOTAL ASSETS | B44: =IFERROR(('HISTORICAL FS'!C17-'HISTORICAL FS'!C23)/'HISTORICAL FS'!C63,0) -> 0.034640756 | C44: =IFERROR(('HISTORICAL FS'!D17-'HISTORICAL FS'!D23)/'HISTORICAL FS'!D63,0) -> 0.06387807 | D44: =IFERROR(('HISTORICAL FS'!E17-'HISTORICAL FS'!E23)/'HISTORICAL FS'!E63,0) -> 0.12086252 | E44: =IFERROR(('HISTORICAL FS'!F17-'HISTORICAL FS'!F23)/'HISTORICAL FS'!F63,0) -> 0.1349828 | F44: =IFERROR(('HISTORICAL FS'!G17-'HISTORICAL FS'!G23)/'HISTORICAL FS'!G63,0) -> 0.11051145 | G44: =IFERROR(('HISTORICAL FS'!H17-'HISTORICAL FS'!H23)/'HISTORICAL FS'!H63,0) -> 0.14651281 | H44: =IFERROR(('HISTORICAL FS'!I17-'HISTORICAL FS'!I23)/'HISTORICAL FS'!I63,0) -> 0.091570466 | I44: =IFERROR(('HISTORICAL FS'!J17-'HISTORICAL FS'!J23)/'HISTORICAL FS'!J63,0) -> 0.061476556 | ... K44: =IFERROR(('HISTORICAL FS'!L17-'HISTORICAL FS'!L23)/'HISTORICAL FS'!L63,0) -> 0.070298724 | M44: =IFERROR(AVERAGE(B44:K44),0) -> 0.090782155 | N44: =IFERROR(AVERAGE(C44:L44),0) -> 0.097020088
A45: PAT AFTER TAX BENEFIT vs TOTAL ASSET | B45: =IFERROR((('HISTORICAL FS'!C17-'HISTORICAL FS'!C23)-('HISTORICAL FS'!C20-('HISTORICAL FS'!C20*'HISTORICAL FS'!C30)))/'HISTORICAL FS'!C63,0) -> 0.021516236 | C45: =IFERROR((('HISTORICAL FS'!D17-'HISTORICAL FS'!D23)-('HISTORICAL FS'!D20-('HISTORICAL FS'!D20*'HISTORICAL FS'!D30)))/'HISTORICAL FS'!D63,0) -> 0.058327906 | D45: =IFERROR((('HISTORICAL FS'!E17-'HISTORICAL FS'!E23)-('HISTORICAL FS'!E20-('HISTORICAL FS'!E20*'HISTORICAL FS'!E30)))/'HISTORICAL FS'!E63,0) -> 0.11611577 | E45: =IFERROR((('HISTORICAL FS'!F17-'HISTORICAL FS'!F23)-('HISTORICAL FS'!F20-('HISTORICAL FS'!F20*'HISTORICAL FS'!F30)))/'HISTORICAL FS'!F63,0) -> 0.13242989 | F45: =IFERROR((('HISTORICAL FS'!G17-'HISTORICAL FS'!G23)-('HISTORICAL FS'!G20-('HISTORICAL FS'!G20*'HISTORICAL FS'!G30)))/'HISTORICAL FS'!G63,0) -> 0.10805776 | G45: =IFERROR((('HISTORICAL FS'!H17-'HISTORICAL FS'!H23)-('HISTORICAL FS'!H20-('HISTORICAL FS'!H20*'HISTORICAL FS'!H30)))/'HISTORICAL FS'!H63,0) -> 0.14512559 | H45: =IFERROR((('HISTORICAL FS'!I17-'HISTORICAL FS'!I23)-('HISTORICAL FS'!I20-('HISTORICAL FS'!I20*'HISTORICAL FS'!I30)))/'HISTORICAL FS'!I63,0) -> 0.090443007 | I45: =IFERROR((('HISTORICAL FS'!J17-'HISTORICAL FS'!J23)-('HISTORICAL FS'!J20-('HISTORICAL FS'!J20*'HISTORICAL FS'!J30)))/'HISTORICAL FS'!J63,0) -> 0.060590011 | ... K45: =IFERROR((('HISTORICAL FS'!L17-'HISTORICAL FS'!L23)-('HISTORICAL FS'!L20-('HISTORICAL FS'!L20*'HISTORICAL FS'!L30)))/'HISTORICAL FS'!L63,0) -> 0.068638274 | M45: =IFERROR(AVERAGE(B45:K45),0) -> 0.087218997 | N45: =IFERROR(AVERAGE(C45:L45),0) -> 0.094519304
A47: RETURN ON EQUITY
A48: EPS | B48: =IFERROR('HISTORICAL FS'!C37,0) -> 3.221044 | C48: =IFERROR('HISTORICAL FS'!D37,0) -> 7.7406199 | D48: =IFERROR('HISTORICAL FS'!E37,0) -> 23.503263 | E48: =IFERROR('HISTORICAL FS'!F37,0) -> 30.889886 | F48: =IFERROR('HISTORICAL FS'!G37,0) -> 31.267537 | G48: =IFERROR('HISTORICAL FS'!H37,0) -> 52.763353 | H48: =IFERROR('HISTORICAL FS'!I37,0) -> 42.593632 | I48: =IFERROR('HISTORICAL FS'!J37,0) -> 30.990902 | ... K48: =IFERROR('HISTORICAL FS'!L37,0) -> 59.376229 | M48: =IFERROR(AVERAGE(B48:K48),0) -> 33.223334 | N48: =IFERROR(AVERAGE(C48:L48),0) -> 36.556922
A49: Cash flow earning per share | B49: =IFERROR(('HISTORICAL FS'!C32+'HISTORICAL FS'!C23)/'HISTORICAL FS'!C35,0) -> 7.9624796 | C49: =IFERROR(('HISTORICAL FS'!D32+'HISTORICAL FS'!D23)/'HISTORICAL FS'!D35,0) -> 12.91354 | D49: =IFERROR(('HISTORICAL FS'!E32+'HISTORICAL FS'!E23)/'HISTORICAL FS'!E35,0) -> 29.47553 | E49: =IFERROR(('HISTORICAL FS'!F32+'HISTORICAL FS'!F23)/'HISTORICAL FS'!F35,0) -> 38.003263 | F49: =IFERROR(('HISTORICAL FS'!G32+'HISTORICAL FS'!G23)/'HISTORICAL FS'!G35,0) -> 40.013051 | G49: =IFERROR(('HISTORICAL FS'!H32+'HISTORICAL FS'!H23)/'HISTORICAL FS'!H35,0) -> 61.537834 | H49: =IFERROR(('HISTORICAL FS'!I32+'HISTORICAL FS'!I23)/'HISTORICAL FS'!I35,0) -> 52.605762 | I49: =IFERROR(('HISTORICAL FS'!J32+'HISTORICAL FS'!J23)/'HISTORICAL FS'!J35,0) -> 42.367703 | ... K49: =IFERROR(('HISTORICAL FS'!L32+'HISTORICAL FS'!L23)/'HISTORICAL FS'!L35,0) -> 81.150134 | M49: =IFERROR(AVERAGE(B49:K49),0) -> 43.61931 | N49: =IFERROR(AVERAGE(C49:L49),0) -> 47.58118
...

Sheet FORECASTING
B2: ='Data Sheet'!B1& " - "&'Data Sheet'!A17 -> ESCORTS KUBOTA LTD - Sales
B3: YEAR WEIGHT | C3: YEAR | D3: SALES | E3: SALES GROWTH
B4: 1 | C4: 2016A | D4: 3431.99 | E4: -
B5: 2 | C5: 2017A | D5: 4145.33 | E5: =D5/D4-1 -> 0.20785026
B6: 3 | C6: 2018A | D6: 5059.34 | E6: =D6/D5-1 -> 0.22049149
B7: 4 | C7: 2019A | D7: 6262.02 | E7: =D7/D6-1 -> 0.2377148
B8: 5 | C8: 2020A | D8: 5810.09 | E8: =D8/D7-1 -> -0.072170003
B9: 6 | C9: 2021A | D9: 7014.42 | E9: =D9/D8-1 -> 0.2072825
B10: 7 | C10: 2022A | D10: 7282.65 | E10: =D10/D9-1 -> 0.038239797
B11: 8 | C11: 2023A | D11: 8428.69 | E11: =D11/D10-1 -> 0.15736579
B12: 9 | C12: 2024A | D12: 9803.59 | E12: =D12/D11-1 -> 0.16312143
B13: 10 | C13: 2025A | D13: 10243.88 | E13: =D13/D12-1 -> 0.044911099
B14: 11 | C14: 2026E | D14: =FORECAST(B14,$D$4:$D$13,$B$4:$B$13) -> 10815.793 | E14: =D14/D13-1 -> 0.055829757
B15: 12 | C15: 2027E | D15: =FORECAST(B15,$D$4:$D$13,$B$4:$B$13) -> 11555.356 | E15: =D15/D14-1 -> 0.06837801
B16: 13 | C16: 2028E | D16: =FORECAST(B16,$D$4:$D$13,$B$4:$B$13) -> 12294.918 | E16: =D16/D15-1 -> 0.064001701
B17: 14 | C17: 2029E | D17: =FORECAST(B17,$D$4:$D$13,$B$4:$B$13) -> 13034.481 | E17: =D17/D16-1 -> 0.060151878
B18: 15 | C18: 2030E | D18: =FORECAST(B18,$D$4:$D$13,$B$4:$B$13) -> 13774.043 | E18: =D18/D17-1 -> 0.056738926

Sheet BETA
A1: Date | B1: Nifty-50 | C1: ESCO | D1: Nifty-50 Return | E1: ESCO-Return | G1: SUMMARY OUTPUT
A2: 43952 | B2: 9580.3 | C2: 901.36
A3: 43983 | B3: 10302.1 | C3: 1037.82 | D3: =(B3-B2)/B2 -> 0.075342108 | E3: =(C3-C2)/C2 -> 0.15139345 | G3: Regression Statistics
A4: 44013 | B4: 11073.45 | C4: 1131.63 | D4: =(B4-B3)/B3 -> 0.074873084 | E4: =(C4-C3)/C3 -> 0.090391397 | G4: Multiple R | H4: 0.35344824
A5: 44044 | B5: 11387.5 | C5: 1085.32 | D5: =(B5-B4)/B4 -> 0.028360628 | E5: =(C5-C4)/C4 -> -0.04092327 | G5: R Square | H5: 0.12492566
A6: 44075 | B6: 11247.55 | C6: 1315.69 | D6: =(B6-B5)/B5 -> -0.012289791 | E6: =(C6-C5)/C5 -> 0.21225998 | G6: Adjusted R Square | H6: 0.10983817
A7: 44105 | B7: 11642.4 | C7: 1198.44 | D7: =(B7-B6)/B6 -> 0.035105423 | E7: =(C7-C6)/C6 -> -0.089116737 | G7: Standard Error | H7: 0.092741091
A8: 44136 | B8: 12968.95 | C8: 1400.91 | D8: =(B8-B7)/B7 -> 0.11394128 | E8: =(C8-C7)/C7 -> 0.16894463 | G8: Observations | H8: 60
A9: 44166 | B9: 13981.75 | C9: 1257.76 | D9: =(B9-B8)/B8 -> 0.078094217 | E9: =(C9-C8)/C8 -> -0.10218358
A10: 44197 | B10: 13634.6 | C10: 1203.18 | D10: =(B10-B9)/B9 -> -0.024828795 | E10: =(C10-C9)/C9 -> -0.043394606 | G10: ANOVA
A11: 44228 | B11: 14529.15 | C11: 1308.16 | D11: =(B11-B10)/B10 -> 0.065608819 | E11: =(C11-C10)/C10 -> 0.087252115 | H11: df | I11: SS | J11: MS | K11: F | L11: Significance F
A12: 44256 | B12: 14690.7 | C12: 1285.1 | D12: =(B12-B11)/B11 -> 0.011119026 | E12: =(C12-C11)/C11 -> -0.017627813 | G12: Regression | H12: 1 | I12: 0.07121625 | J12: 0.07121625 | K12: 8.2800832 | L12: 0.0056015863
A13: 44287 | B13: 14631.1 | C13: 1116.26 | D13: =(B13-B12)/B12 -> -0.0040569884 | E13: =(C13-C12)/C12 -> -0.13138277 | G13: Residual | H13: 58 | I13: 0.49885278 | J13: 0.00860091
A14: 44317 | B14: 15582.8 | C14: 1169.35 | D14: =(B14-B13)/B13 -> 0.065046374 | E14: =(C14-C13)/C13 -> 0.047560604 | G14: Total | H14: 59 | I14: 0.57006903
A15: 44348 | B15: 15721.5 | C15: 1217.55 | D15: =(B15-B14)/B14 -> 0.0089008394 | E15: =(C15-C14)/C14 -> 0.041219481
A16: 44378 | B16: 15763.05 | C16: 1184.35 | D16: =(B16-B15)/B15 -> 0.0026428776 | E16: =(C16-C15)/C15 -> -0.027267874 | H16: Coefficients | I16: Standard Error | J16: t Stat | K16: P-value | L16: Lower 95% | M16: Upper 95% | N16: Lower 95.0% | O16: Upper 95.0%
A17: 44409 | B17: 17132.2 | C17: 1346.35 | D17: =(B17-B16)/B16 -> 0.086858191 | E17: =(C17-C16)/C16 -> 0.13678389 | G17: Intercept | H17: 0.012100659 | I17: 0.012988631 | J17: 0.93163468 | K17: 0.35538725 | L17: -0.013898911 | M17: 0.038100229 | N17: -0.013898911 | O17: 0.038100229
A18: 44440 | B18: 17618.15 | C18: 1480.1 | D18: =(B18-B17)/B17 -> 0.028364717 | E18: =(C18-C17)/C17 -> 0.099342667 | G18: X Variable 1 | H18: 0.86663737 | I18: 0.30117579 | J18: 2.8775134 | K18: 0.0056015863 | L18: 0.26376852 | M18: 1.4695062 | N18: 0.26376852 | O18: 1.4695062
A19: 44470 | B19: 17671.65 | C19: 1569.4 | D19: =(B19-B18)/B18 -> 0.0030366412 | E19: =(C19-C18)/C18 -> 0.060333761
A20: 44501 | B20: 16983.2 | C20: 1846.3 | D20: =(B20-B19)/B19 -> -0.038957879 | E20: =(C20-C19)/C19 -> 0.17643685
A21: 44531 | B21: 17354.05 | C21: 1908.7 | D21: =(B21-B20)/B20 -> 0.021836285 | E21: =(C21-C20)/C20 -> 0.033797324
A22: 44562 | B22: 17339.85 | C22: 1850.35 | D22: =(B22-B21)/B21 -> -0.0008182528 | E22: =(C22-C21)/C21 -> -0.030570545
A23: 44593 | B23: 16793.9 | C23: 1850.95 | D23: =(B23-B22)/B22 -> -0.031485278 | E23: =(C23-C22)/C22 -> 0.00032426298
A24: 44621 | B24: 17464.75 | C24: 1690.85 | D24: =(B24-B23)/B23 -> 0.039946052 | E24: =(C24-C23)/C23 -> -0.086496124
A25: 44652 | B25: 17102.55 | C25: 1634.85 | D25: =(B25-B24)/B24 -> -0.020738917 | E25: =(C25-C24)/C24 -> -0.033119437
A26: 44682 | B26: 16584.55 | C26: 1629.95 | D26: =(B26-B25)/B25 -> -0.030287881 | E26: =(C26-C25)/C25 -> -0.0029972169
A27: 44713 | B27: 15780.25 | C27: 1444.8 | D27: =(B27-B26)/B26 -> -0.048496944 | E27: =(C27-C26)/C26 -> -0.11359244
A28: 44743 | B28: 17158.25 | C28: 1733 | D28: =(B28-B27)/B27 -> 0.087324345 | E28: =(C28-C27)/C27 -> 0.19947398
A29: 44774 | B29: 17759.3 | C29: 1994.75 | D29: =(B29-B28)/B28 -> 0.035029796 | E29: =(C29-C28)/C28 -> 0.15103866
A30: 44805 | B30: 17094.35 | C30: 2127.8 | D30: =(B30-B29)/B29 -> -0.037442354 | E30: =(C30-C29)/C29 -> 0.066700088
... A62: 45778 | B62: 24750.7 | C62: 3321.7 | D62: =(B62-B61)/B61 -> 0.017115829 | E62: =(C62-C61)/C61 -> 0.01923903
C65: Raw Beta | D65: =SLOPE(E3:E62,D3:D62) -> 0.86663737
C66: Intercept/Alpha | D66: =INTERCEPT(E3:E62,D3:D62) -> 0.012100659
C67: R-Squared | D67: =RSQ(E3:E62,D3:D62) -> 0.12492566
C68: Correlation | D68: =CORREL(E3:E62,D3:D62) -> 0.35344824 | E68: =SQRT(D67) -> 0.35344824
C69: SE of Beta | D69: =STEYX(E3:E62,D3:D62)/(_xlfn.STDEV.S(D3:D62)*SQRT(COUNT(D3:D62)-1)) -> 0.30117579
C70: Variance of Nifty | D70: =_xlfn.VAR.S(D3:D62) -> 0.0016071347
C71: COV of ESCO with Nifty | D71: =_xlfn.COVARIANCE.S(E3:E62,D3:D62) -> 0.001392803
C72: Beta cross check | D72: =D71/D70 -> 0.86663737
C73: Adjusted Beta | D73: =(0.67*D65)+(0.33*1) -> 0.91064704

Sheet WACC
B2: Weighted average cost of capital
B4: All figures are in IRR unless otherwise stated
B6: Peer comps
G7: Debt/ | H7: Debt/ | I7: Levered | J7: Unlevered
B8: Name of the | C8: Country | D8: Total Debt | E8: Total Equity | F8: Tax Rate 1 | G8: Equity | H8: Capital | I8: Beta 2 | J8: Beta 3
B10: VST Tillers | C10: India | D10: 0.01 | E10: 4528 | F10: 0.2517 | G10: =D10/E10 -> 2.2084806e-06 | H10: =D10/(D10+E10) -> 2.2084757e-06 | I10: 0.45 | J10: =I10/(1+(1-F10)*G10) -> 0.44999926
B11: Mahindra & Mahindra | C11: India | D11: 4000 | E11: 359600 | F11: 0.2517 | G11: =D11/E11 -> 0.011123471 | H11: =D11/(D11+E11) -> 0.0110011 | I11: 0.29 | J11: =I11/(1+(1-F11)*G11) -> 0.28760606
B12: Action Construction Equipment | C12: India | D12: 164.37 | E12: 14280 | F12: 0.2517 | G12: =D12/E12 -> 0.011510504 | H12: =D12/(D12+E12) -> 0.01137952 | I12: 0.2 | J12: =I12/(1+(1-F12)*G12) -> 0.19829205
B13: Swaraj Engines | C13: India | D13: 0.01 | E13: 4914 | F13: 0.2517 | G13: =D13/E13 -> 2.035002e-06 | H13: =D13/(D13+E13) -> 2.0349979e-06 | I13: 0.7 | J13: =I13/(1+(1-F13)*G13) -> 0.69999893
B14: Force Motors | C14: India | D14: 500 | E14: 13200 | F14: 0.2517 | G14: =D14/E14 -> 0.037878788 | H14: =D14/(D14+E14) -> 0.03649635 | I14: 0.5 | J14: =I14/(1+(1-F14)*G14) -> 0.48621829
E16: Average | F16: =AVERAGE(F10:F14) -> 0.2517 | G16: =AVERAGE(G10:G14) -> 0.012103401 | H16: =AVERAGE(H10:H14) -> 0.011776243 | I16: =AVERAGE(I10:I14) -> 0.428 | J16: =AVERAGE(J10:J14) -> 0.42442292
E17: Median | F17: =MEDIAN(F10:F14) -> 0.2517 | G17: =MEDIAN(G10:G14) -> 0.011123471 | H17: =MEDIAN(H10:H14) -> 0.0110011 | I17: =MEDIAN(I10:I14) -> 0.45 | J17: =MEDIAN(J10:J14) -> 0.44999926
B20: Cost of Debt | G20: Cost of Equity
B22: Pre cost tax of debt | E22: 0.085 | G22: Risk free rate | K22: 0.0622
B23: Tax rate | E23: 0.2517 | G23: Equity risk premium | K23: 0.08
B24: Post tax cost of debt | E24: =E22*(1-E23) -> 0.0636055 | G24: Levered Beta 4 | K24: =K33 -> 0.45104712
G25: Cost of Equity | K25: =K22+(K23*BETA!D73) -> 0.13505176
B28: Capital structure | G28: Levered Beta
D30: Current | E30: Target | G30: Comps Median Unlevered Beta | K30: =I17 -> 0.45
B31: Total Debt | C31: 105.58 | D31: =C31/$C$33 -> 0.0028464067 | E31: 0.0031 | G31: Target Debt/Equity | K31: =E35 -> 0.0031096399
B32: Market Capitalization | C32: ='Data Sheet'!B9 -> 36986.8 | D32: =C32/$C$33 -> 0.99715359 | E32: =E33-E31 -> 0.9969 | G32: Tax Rate | K32: =E23 -> 0.2517
B33: Total Capital | C33: =C31+C32 -> 37092.38 | D33: =C33/$C$33 -> 1 | E33: 1 | G33: Levered Beta | K33: =K30*(1+(1-K32)*K31) -> 0.45104712
B35: Debt/ Equity | D35: =D31/D32 -> 0.0028545319 | E35: =E31/E32 -> 0.0031096399 | G35: Weighted Average Cost of Capital
K36: Total cost | L36: Total Weight
G37: Debt | K37: =E24 -> 0.0636055 | L37: =E31 -> 0.0031
G38: Equity | K38: =K25 -> 0.13505176 | L38: =E32 -> 0.9969
G39: Weighted Average Cost of Capital | L39: =SUMPRODUCT(K37:K38,L37:L38) -> 0.13483028

Sheet VARIANCE ANALYSIS
A1: Line Item | B1: Actual FY25 | C1: Forecasted FY25(best case) | D1: Variance ₹ Cr (vs Best) | E1: Variance % (vs Best) | F1: Forecasted FY25(Worst case) | G1: Variance ₹ Cr (vs worst) | H1: Variance % (vs Worst) | I1: F/U | J1: Reason/Commentary
A3: Sales | B3: ='Profit & Loss'!K4 -> 10243.88 | C3: ='Profit & Loss'!M4 -> 11477.734 | D3: =B3-C3 -> -1233.8542 | E3: =(B3-C3)/ABS(C3) -> -0.10749981 | F3: ='Profit & Loss'!N4 -> 10714.932 | G3: =(B3-C3)/ABS(C3) -> -0.10749981 | H3: =(B3-F3)/ABS(F3) -> -0.043962189 | I3: =IF(D3>0,"Favourable",IF(D3<0,"Unfavourable","Nil")) -> Unfavourable | J3: Actual ₹10,244 Cr vs Best Case ₹11,478 Cr — missed by ₹1,234 Cr (10.7%) due to FY25 actual growth of only 4.5% vs assumed growth rate of ~12% in Best Case projection
A4: Expenses | B4: ='Profit & Loss'!K5 -> 9079.69 | C4: ='Profit & Loss'!M5 -> 10146.23 | D4: =B4-C4 -> -1066.5402 | E4: =(B4-C4)/ABS(C4) -> -0.10511689 | F4: ='Profit & Loss'!N5 -> 9561.7925 | G4: =(B4-C4)/ABS(C4) -> -0.10511689 | H4: =(B4-F4)/ABS(F4) -> -0.05041968 | I4: =IF(D4<0,"Favourable",IF(D4>0,"Unfavourable","Nil")) -> Favourable
A5: Operating Profit | B5: ='Profit & Loss'!K6 -> 1164.19 | C5: ='Profit & Loss'!M6 -> 1331.504 | D5: =B5-C5 -> -167.31401 | E5: =(B5-C5)/ABS(C5) -> -0.12565791 | F5: ='Profit & Loss'!N6 -> 1153.1393 | G5: =(B5-C5)/ABS(C5) -> -0.12565791 | H5: =(B5-F5)/ABS(F5) -> 0.0095831145 | I5: =IF(D5>0,"Favourable",IF(D5<0,"Unfavourable","Nil")) -> Unfavourable | J5: Actual ₹1,164 Cr slightly below Best Case ₹1,331 Cr — OPM compressed to 11.4% vs assumed 11.6%
A6: Other Income | B6: ='Profit & Loss'!K7 -> 600.53 | C6: ='Profit & Loss'!M7 -> 0 | D6: =B6-C6 -> 600.53 | E6: =IFERROR((B6 - C6) / ABS(C6), "N/A-Not Forecasted") -> N/A-Not Forecasted | F6: ='Profit & Loss'!N7 -> 0 | G6: =IFERROR((B6 - C6) / ABS(C6), "N/A - Not Forecasted") -> N/A - Not Forecasted | H6: =IFERROR((B6 - F6) / ABS(F6), "N/A - Not Forecasted") -> N/A - Not Forecasted | I6: =IF(D6>0,"Favourable",IF(D6<0,"Unfavourable","Nil")) -> Favourable | J6: Actual ₹600 Cr vs Best Case ₹0 — Best Case model excluded other income conservatively; actual other income from ₹5,605 Cr investment portfolio significantly boosted reported profits
A7: Depreciation | B7: ='Profit & Loss'!K8 -> 243.65 | C7: ='Profit & Loss'!M8 -> 246.2 | D7: =B7-C7 -> -2.55 | E7: =(B7-C7)/ABS(C7) -> -0.010357433 | F7: ='Profit & Loss'!N8 -> 246.2 | G7: =(B7-C7)/ABS(C7) -> -0.010357433 | H7: =(B7-F7)/ABS(F7) -> -0.010357433 | I7: =IF(D7<0,"Favourable",IF(D7>0,"Unfavourable","Nil")) -> Favourable
A8: Interest | B8: ='Profit & Loss'!K9 -> 29.17 | C8: ='Profit & Loss'!M9 -> 29.2 | D8: =B8-C8 -> -0.03 | E8: =(B8-C8)/ABS(C8) -> -0.0010273973 | F8: ='Profit & Loss'!N9 -> 29.2 | G8: =(B8-C8)/ABS(C8) -> -0.0010273973 | H8: =(B8-F8)/ABS(F8) -> -0.0010273973 | I8: =IF(D8<0,"Favourable",IF(D8>0,"Unfavourable","Nil")) -> Favourable
